<?xml version='1.0'?>

<robot name="my_robot" xmlns:xacro="https://www.ros.org/wiki/xacro">
    <!-- Colors -->
    <material name="blue">
        <color rgba="0 0 0.8 1"/>
    </material>
    <material name="black">
        <color rgba="0 0 0 1"/>
    </material>
    <material name="white">
        <color rgba="1 1 1 1"/>
    </material>
    <material name="green">
        <color rgba="0 0.5 0 1"/>
    </material>
    
    <!-- Plugins -->
    <xacro:include filename="$(find my_robot)/urdf/my_robot.gazebo"/>
    
    <link name="robot_footprint"></link>

    <joint name="robot_footprint_joint" type="fixed">
        <origin xyz="0 0 0" rpy="0 0 0"/>
        <parent link="robot_footprint"/>
        <child link="chassis"/>
    </joint>

    <link name="chassis">
        <pose>0 0 0.1 0 0 0</pose>
        <inertial>
            <mass value="15.0"/>
            <origin xyz="0.0 0 0" rpy="0 0 0"/>
            <inertia 
                ixx="0.1" ixy="0" ixz="0"
                iyy="0.1" iyz="0"
                izz="0.1"
                />
        </inertial>

        <collision name="collision">
            <origin xyz="0 0 0" rpy="0 0 0"/>
            <geometry>
                <box size=".4 .2 .1"/>
            </geometry>
        </collision>

        <visual name="chassis_visual">
            <origin xyz="0 0 0" rpy="0 0 0"/>
            <geometry>
                <box size=".4 .2 .1"/>
                <material name="green">
                    <color rgba="1 0 0 1"/>
                </material>
            </geometry>
        </visual>

        <collision name="back_caster_collision">
            <origin xyz="-0.15 0 -0.05" rpy="0 0 0"/>
            <geometry>
                <sphere radius="0.0499"/>
            </geometry>
        </collision>

        <visual name="back_caster_visual">
            <origin xyz="-0.15 0 -0.05" rpy="0 0 0"/>
            <geometry>
                <sphere radius="0.05"/>
            </geometry>
        </visual>

        <collision name="front_caster_collision">
            <origin xyz="0.15 0 -0.05" rpy="0 0 0"/>
            <geometry>
                <sphere radius="0.0499"/>
            </geometry>
        </collision>

        <visual name="front_caster_visual">
            <origin xyz="0.15 0 -0.05" rpy="0 0 0"/>
            <geometry>
                <sphere radius="0.05"/>
            </geometry>
        </visual>
    </link>
    <link name="LEFT_wheel" >
        <inertial>
            <origin xyz="0 0 0" rpy="0 1.5707 1.5707"/>
            <mass value="5"/>
            <geometry>
                <cylinder radius="0.1" length="0.05"/>
            </geometry>
            <inertia 
                ixx="0.1" ixy="0" ixz="0"
                iyy="0.1" iyz="0"
                izz="0.1"
                />
        </inertial> 
        <visual>
            <origin xyz="0 0 0" rpy="0 1.5707 1.5707"/>
            <geometry>
                <cylinder radius="0.1" length="0.05"/>
            </geometry>
        </visual>
        <collision>
            <origin xyz="0 0 0" rpy="0 1.5707 1.5707"/>
            <geometry>
                <cylinder radius="0.1" length="0.05"/>
            </geometry>
        </collision>
    </link>

    <joint type="continuous" name="left_wheel_hinge">
        <origin xyz="0 0.15 0" rpy="0 0 0"/>
        <child link="LEFT_wheel"/>
        <parent link="chassis"/>
        <axis xyz="0 1 0" rpy="0 0 0"/>
        <limit effort="10000" velocity="1000"/>
        <dynamics damping="1.0" friction="1.0"/>
    </joint>

    <link name="RIGHT_wheel">
        <inertial>
            <origin xyz="0 0 0" rpy="0 1.5707 1.5707"/>
            <mass value="5"/>
            <geometry>
                <cylinder radius="0.1" length="0.05"/>
            </geometry>
            <inertia
                ixx="1.0" ixy="0" ixz="0"
                iyy="1.0" iyz="0"
                izz="1.0"/>
        </inertial>
        <visual>
            <origin xyz="0 0 0" rpy="0 1.5707 1.5707"/>
            <material name="blue"/>
            <geometry>
                <cylinder radius="0.1" length="0.05"/>
            </geometry>
        </visual>
        <collision>
            <origin xyz="0 0 0" rpy="0 1.5707 1.5707"/>
            <geometry> 
                <cylinder radius="0.1" length="0.05"/>
            </geometry>
        </collision> 
    </link>
    <joint type="continuous" name="right_wheel_hinge">
        <origin xyz="0 -0.15 0" rpy="0 0 0"/>
        <child link="RIGHT_wheel"/>
        <parent link="chassis"/>
        <axis xyz="0 1 0" rpy="0 0 0"/>
        <limits effort="10000" velocity="1000"/>
        <dynamics damping="1.0" friction="1.0"/>
    </joint>

    <link name="camera">
        <inertial>
            <origin xyz="0 0 0" rpy="0 0 0"/>
            <mass value="0.1"/>
            <inertia 
                ixx="1e-6" ixy="0" ixz="0"
                iyy="1e-6" iyz="0"
                izz="1e-6"/>
        </inertial>
        <visual>
            <origin xyz="0 0 0" rpy="0 0 0"/>
            <geometry>
                <box size=".05 .05 .05"/>
            </geometry>
            <box_inertia m="0.1" x="0.05" y="0.05" z="0.05"/>
        </visual>
        <collision>
            <origin xyz="0 0 0" rpy="0 0 0"/>
            <geometry>
                <box size=".05 .05 .05"/>
            </geometry>
            <box_inertia m="0.1" x="0.05" y="0.05" z="0.05"/>
        </collision>
    </link>
    <joint type="fixed" name="camera_joint" >
        <origin xyz="0.20 0 0" rpy="0 0 0"/>
        <axis xyz="0 1 0"/>
        <child link="camera"/>
        <parent link="chassis"/>
    </joint>

    <!-- Add the hokuyo -->
    <link name="hokuyo">
        <inertial>
            <origin xyz="0 0 0" rpy="0 0 0"/> 
            <mass value="1e-5"/>
            <inertia 
                ixx="1e-6" ixy="0" ixz="0"
                iyy="1e-6" iyz="0"
                izz="1e-6"/>
        </inertial>
        <visual>
            <origin xyz="0 0 0" rpy="0 0 0"/> 
            <geometry> <mesh filename="package://my_robot/meshes/hokuyo.dae"/> </geometry>
        </visual>
        <collision>
            <origin xyz="0 0 0" rpy="0 0 0"/> 
            <geometry>
                <box size="0.1 0.1 0.1"/>
            </geometry>
        </collision>
    </link>
    <joint name="hokuyo_joint" type="fixed">
        <origin xyz="0.15 0 .1" rpy="0 0 0"/>
        <axis xyz="0 1 0"/>
        <child link="hokuyo"/>
        <parent link="chassis"/>
        <limit effort="10000" velocity="0"/>
        <dynamics damping="1.0" friction="1.0"/>
    </joint>

    <gazebo reference="chassis">
        <material>Gazebo/Green</material>
    </gazebo>

    <gazebo reference="LEFT_wheel">
        <material>Gazebo/Blue</material>
    </gazebo>

    <gazebo reference="RIGHT_wheel">
        <material>Gazebo/Blue</material>
    </gazebo>

    <gazebo reference="camera">
        <material>Gazebo/Red</material>
    </gazebo>

    <gazebo reference="back_caster_visual">
        <material>Gazebo/Red</material>
    </gazebo>

</robot>

